<?xml version="1.0"?>
<robot xmlns:xacro="http://www.ros.org/wiki/xacro" >
<xacro:include filename="inertial_macros.xacro" />
<xacro:include filename="lidar.xacro" />


    <material name="white">
        <color rgba="1 1 1 1" />
    </material>

    <material name="orange">
        <color rgba="1 0.3 0.1 1"/>
    </material>

    <material name="blue">
        <color rgba="0.2 0.2 1 1"/>
    </material>

    <material name="black">
        <color rgba="0 0 0 1"/>
    </material>

    <material name="red">
        <color rgba="1 0 0 1"/>
    </material>

    <!-- BASE LINK -->

    <link name="base_link">
    </link>

    <!-- BASE_FOOTPRINT LINK -->

    <joint name="base_footprint_joint" type="fixed">
    <parent link="base_link"/>
    <child link="base_footprint"/>
    <origin xyz="0 0 0" rpy="0 0 0"/>
    </joint>

    <link name="base_footprint">
    </link>

    <!--BODIOOOO-->
    <joint name="Body_joint2" type="fixed">
    <parent link="base_link"/>
    <child link="body"/>
    <origin xyz="0 0 0"/>
    <dynamics friction="100"/>
    </joint>

    <link name="body">
    <visual>
        <origin xyz="0 0 0" rpy="0 0 0"/>
        <geometry>
            <mesh filename="file:///home/tiis/yeehee_ws/src/articubot_one/description/body1.dae" scale="1 1 1"/>

        </geometry>
    </visual>
    <collision>
        <origin xyz="0 0 0" rpy="0 0 0"/>
        <geometry>
            <mesh filename="file:///home/tiis/yeehee_ws/src/articubot_one/description/body1.dae" scale="1 1 1"/>
        </geometry>
    </collision>
    <xacro:inertial_box mass="10" x="0.7" y="0.4" z="0.1">
        <origin xyz="0 0 0.25" rpy="0 0 0"/>
    </xacro:inertial_box>
    </link>



    <!--FRONT LEFTY-->
    <joint name="LFW_joint" type="continuous">
    <parent link="base_link"/>
    <child link="LFW"/>
    <origin xyz="0.225 0.3 0" rpy="-${pi/2} 0 0"/>
    <axis xyz="0 0 1"/>
    </joint>

    <link name="LFW">
    <visual>
        <origin xyz="0 0 0" rpy="0 0 0"/>
        <geometry>
            <cylinder length="0.05" radius="0.125" />
        </geometry>
        <material name="red"/>
    </visual>
    <collision>
        <origin xyz="0 0 0" rpy="0 0 0"/>
        <geometry>
            <cylinder length="0.05" radius="0.125" />
        </geometry>
    </collision>
    <xacro:inertial_cylinder mass="3" length="0.05" radius="0.125">
        <origin xyz="0 0 0" rpy="0 0 0"/>
    </xacro:inertial_cylinder>
    <mu1 value="0.001"/>
    <mu2 value="0.001"/>
    </link>



    <!--FRONT RIGHTY-->
    <joint name="RFW_joint" type="continuous">
    <parent link="base_link"/>
    <child link="RFW"/>
    <origin xyz="0.225 -0.3 0" rpy="-${pi/2} 0 0"/>
    <axis xyz="0 0 1"/>
    </joint>

    <link name="RFW">
    <visual>
        <origin xyz="0 0 0" rpy="0 0 0"/>
        <geometry>
            <cylinder length="0.05" radius="0.125" />
        </geometry>
        <material name="red"/>
    </visual>
    <collision>
        <origin xyz="0 0 0" rpy="0 0 0"/>
        <geometry>
            <cylinder length="0.05" radius="0.125" />
        </geometry>
    </collision>
    <xacro:inertial_cylinder mass="3" length="0.05" radius="0.125">
        <origin xyz="0 0 0" rpy="0 0 0"/>
    </xacro:inertial_cylinder>
    <mu1 value="0.001"/>
    <mu2 value="0.001"/>
    </link>



    <!--REAR LEFTY-->
    <joint name="RLW_joint" type="continuous">
    <parent link="base_link"/>
    <child link="RLW"/>
    <origin xyz="-0.225 0.3 0" rpy="-${pi/2} 0 0"/>
    <axis xyz="0 0 1"/>
    </joint>

    <link name="RLW">
    <visual>
        <origin xyz="0 0 0" rpy="0 0 0"/>
        <geometry>
            <cylinder length="0.05" radius="0.125" />
        </geometry>
        <material name="red"/>
    </visual>
    <collision>
        <origin xyz="0 0 0" rpy="0 0 0"/>
        <geometry>
            <cylinder length="0.05" radius="0.125" />
        </geometry>
    </collision>
    <xacro:inertial_cylinder mass="3" length="0.05" radius="0.125">
        <origin xyz="0 0 0" rpy="0 0 0"/>
    </xacro:inertial_cylinder>
    <mu1 value="0.001"/>
    <mu2 value="0.001"/>
    </link>



    <!--REAR RIGHTY-->   
    <joint name="RRW_joint" type="continuous">
    <parent link="base_link"/>
    <child link="RRW"/>
    <origin xyz="-0.225 -0.3 0" rpy="-${pi/2} 0 0"/>
    <axis xyz="0 0 1"/>
    </joint>

    <link name="RRW">
    <visual>
        <origin xyz="0 0 0" rpy="0 0 0"/>
        <geometry>
            <cylinder length="0.05" radius="0.125" />
        </geometry>
        <material name="red"/>
    </visual>
    <collision>
        <origin xyz="0 0 0" rpy="0 0 0"/>
        <geometry>
            <cylinder length="0.05" radius="0.125" />
        </geometry>
    </collision>
    <xacro:inertial_cylinder mass="3" length="0.05" radius="0.125">
        <origin xyz="0 0 0" rpy="0 0 0"/>
    </xacro:inertial_cylinder>
    <mu1 value="0.001"/>
    <mu2 value="0.001"/>
    </link>


    <!-- Fixed younggu -->
    <joint name="cy_joint" type="revolute">
    <parent link="base_link"/>
    <child link="cy"/>
    <origin xyz="-0.25 0 0.35"/>
    <axis xyz="0 0 1"/>
    <limit lower="0" upper="${pi}" velocity="0.1" effort="100" />
    </joint>

    <link name="cy">
    <visual>
        <origin xyz="0 0 0" rpy="0 0 0"/>
        <geometry>
            <cylinder length="0.15" radius="0.12" />
        </geometry>
        <material name="white"/>
    </visual>
    <collision>
        <origin xyz="0 0 0" rpy="0 0 0"/>
        <geometry>
            <cylinder length="0.15" radius="0.12" />
        </geometry>
    </collision>
    <xacro:inertial_cylinder mass="0.1" length="0.15" radius="0.12">
        <origin xyz="0 0 0" rpy="0 0 0"/>
    </xacro:inertial_cylinder>
    </link>   
    
    
    <!-- Grip1 -->

    <joint name="grip1_joint" type="revolute">
    <parent link="cy"/>
    <child link="grip1"/>
    <origin xyz="0.075 0 0.075"/>
    <limit lower="0" upper="${pi/2}" velocity="0.1" effort="100" />
    <axis xyz="0 1 0"/>
    </joint>

    <link name="grip1">
    <visual>
        <origin xyz="-0.075 0 0.2" rpy="${-pi/2} ${-pi/2} 0"/>
        <geometry>
            <box size="0.4 0.15 0.1"/>
        </geometry>
        <material name="white"/>
    </visual>
    <collision>
        <origin xyz="-0.075 0 0.2" rpy="${-pi/2} ${-pi/2} 0"/>
        <geometry>
            <box size="0.4 0.15 0.15"/>
        </geometry>
    </collision>
    <xacro:inertial_box mass="0.08" x="0.5" y="0.15" z="0.1">
        <origin xyz="-0.075 0 0.2" rpy="${-pi/2} ${-pi/2} 0"/>
    </xacro:inertial_box>
    </link>
    
    <!-- GripFing 1 -->
    <joint name="gf1_joint" type="revolute">
    <parent link="grip1"/>
    <child link="gf1"/>
    <origin xyz="0 -0.05 0.4"/>
    <limit lower="0" upper="${pi/12}" velocity="0.1" effort="100" />
    <axis xyz="0 0 1"/>
    </joint>
    
    <link name="gf1">
    <visual>
      <origin xyz="0.075 -0.05 -0.05" rpy="${-pi/2} ${-pi/2} 0"/>
      <geometry>
        <box size="0.1 0.15 0.1"/>
      </geometry>
      <material name="blue"/>
    </visual>
    <collision>
      <origin xyz="0.075 -0.05 -0.05" rpy="${-pi/2} ${-pi/2} 0"/>
      <geometry>
        <box size="0.1 0.15 0.1"/>
      </geometry>
      </collision>
    <xacro:inertial_box mass="0.02" x="0.1" y="0.15" z="0.1">
      <origin xyz="0.075 -0.05 -0.05" rpy="${-pi/2} ${-pi/2} 0"/>
    </xacro:inertial_box>
  </link>
    
    <!-- GripFing 2 -->
    <joint name="gf2_joint" type="revolute">
    <parent link="grip1"/>
    <child link="gf2"/>
    <origin xyz="0 0.05 0.4"/>
    <limit lower="0" upper="${-pi/12}" velocity="0.1" effort="100" />
    <axis xyz="0 0 1"/>
    <mimic joint="gf1_joint" multiplier="-1.0" offset="0.0"/> 
    </joint>

    <link name="gf2">
    <visual>
      <origin xyz="0.075 0.05 -0.05" rpy="${-pi/2} ${-pi/2} 0"/>
      <geometry>
        <box size="0.1 0.15 0.1"/>
      </geometry>
      <material name="blue"/>
    </visual>
    <collision>
      <origin xyz="0.075 0.05 -0.05" rpy="${-pi/2} ${-pi/2} 0"/>
      <geometry>
        <box size="0.1 0.15 0.1"/>
      </geometry>
      </collision>
    <xacro:inertial_box mass="0.02" x="0.1" y="0.15" z="0.1">
      <origin xyz="0.075 0.05 -0.05" rpy="${-pi/2} ${-pi/2} 0"/>
    </xacro:inertial_box>
  </link>



</robot>